================================================================================
SUPERSCAN END-TO-END TEST CASE
Test Data: Harshit's Resume PDF
================================================================================

ðŸ“‹ PHASE 1: Setup & Initialization
--------------------------------------------------------------------------------
  âœ“ Initializing Snowflake database...
Traceback (most recent call last):
  File "/opt/miniconda3/lib/python3.12/site-packages/sqlalchemy/engine/base.py", line 145, in __init__
    self._dbapi_connection = engine.raw_connection()
                             ^^^^^^^^^^^^^^^^^^^^^^^
  File "/opt/miniconda3/lib/python3.12/site-packages/sqlalchemy/engine/base.py", line 3297, in raw_connection
    return self.pool.connect()
           ^^^^^^^^^^^^^^^^^^^
  File "/opt/miniconda3/lib/python3.12/site-packages/sqlalchemy/pool/base.py", line 449, in connect
    return _ConnectionFairy._checkout(self)
           ^^^^^^^^^^^^^^^^^^^^^^^^^^^^^^^^
  File "/opt/miniconda3/lib/python3.12/site-packages/sqlalchemy/pool/base.py", line 1264, in _checkout
    fairy = _ConnectionRecord.checkout(pool)
            ^^^^^^^^^^^^^^^^^^^^^^^^^^^^^^^^
  File "/opt/miniconda3/lib/python3.12/site-packages/sqlalchemy/pool/base.py", line 713, in checkout
    rec = pool._do_get()
          ^^^^^^^^^^^^^^
  File "/opt/miniconda3/lib/python3.12/site-packages/sqlalchemy/pool/impl.py", line 179, in _do_get
    with util.safe_reraise():
  File "/opt/miniconda3/lib/python3.12/site-packages/sqlalchemy/util/langhelpers.py", line 224, in __exit__
    raise exc_value.with_traceback(exc_tb)
  File "/opt/miniconda3/lib/python3.12/site-packages/sqlalchemy/pool/impl.py", line 177, in _do_get
    return self._create_connection()
           ^^^^^^^^^^^^^^^^^^^^^^^^^
  File "/opt/miniconda3/lib/python3.12/site-packages/sqlalchemy/pool/base.py", line 390, in _create_connection
    return _ConnectionRecord(self)
           ^^^^^^^^^^^^^^^^^^^^^^^
  File "/opt/miniconda3/lib/python3.12/site-packages/sqlalchemy/pool/base.py", line 675, in __init__
    self.__connect()
  File "/opt/miniconda3/lib/python3.12/site-packages/sqlalchemy/pool/base.py", line 901, in __connect
    with util.safe_reraise():
  File "/opt/miniconda3/lib/python3.12/site-packages/sqlalchemy/util/langhelpers.py", line 224, in __exit__
    raise exc_value.with_traceback(exc_tb)
  File "/opt/miniconda3/lib/python3.12/site-packages/sqlalchemy/pool/base.py", line 897, in __connect
    self.dbapi_connection = connection = pool._invoke_creator(self)
                                         ^^^^^^^^^^^^^^^^^^^^^^^^^^
  File "/opt/miniconda3/lib/python3.12/site-packages/sqlalchemy/engine/create.py", line 646, in connect
    return dialect.connect(*cargs, **cparams)
           ^^^^^^^^^^^^^^^^^^^^^^^^^^^^^^^^^^
  File "/opt/miniconda3/lib/python3.12/site-packages/snowflake/sqlalchemy/snowdialect.py", line 900, in connect
    super().connect(
  File "/opt/miniconda3/lib/python3.12/site-packages/sqlalchemy/engine/default.py", line 625, in connect
    return self.loaded_dbapi.connect(*cargs, **cparams)  # type: ignore[no-any-return]  # NOQA: E501
           ^^^^^^^^^^^^^^^^^^^^^^^^^^^^^^^^^^^^^^^^^^^^
  File "/opt/miniconda3/lib/python3.12/site-packages/snowflake/connector/__init__.py", line 54, in Connect
    return SnowflakeConnection(**kwargs)
           ^^^^^^^^^^^^^^^^^^^^^^^^^^^^^
  File "/opt/miniconda3/lib/python3.12/site-packages/snowflake/connector/connection.py", line 588, in __init__
    self.connect(**kwargs)
  File "/opt/miniconda3/lib/python3.12/site-packages/snowflake/connector/connection.py", line 972, in connect
    self.__open_connection()
  File "/opt/miniconda3/lib/python3.12/site-packages/snowflake/connector/connection.py", line 1371, in __open_connection
    self.authenticate_with_retry(self.auth_class)
  File "/opt/miniconda3/lib/python3.12/site-packages/snowflake/connector/connection.py", line 1704, in authenticate_with_retry
    self._authenticate(auth_instance)
  File "/opt/miniconda3/lib/python3.12/site-packages/snowflake/connector/connection.py", line 1736, in _authenticate
    auth.authenticate(
  File "/opt/miniconda3/lib/python3.12/site-packages/snowflake/connector/auth/_auth.py", line 401, in authenticate
    Error.errorhandler_wrapper(
  File "/opt/miniconda3/lib/python3.12/site-packages/snowflake/connector/errors.py", line 286, in errorhandler_wrapper
    handed_over = Error.hand_to_other_handler(
                  ^^^^^^^^^^^^^^^^^^^^^^^^^^^^
  File "/opt/miniconda3/lib/python3.12/site-packages/snowflake/connector/errors.py", line 344, in hand_to_other_handler
    connection.errorhandler(connection, cursor, error_class, error_value)
  File "/opt/miniconda3/lib/python3.12/site-packages/snowflake/connector/errors.py", line 217, in default_errorhandler
    raise error_class(
snowflake.connector.errors.DatabaseError: 250001 (08001): Failed to connect to DB: 1234567890@FHWELTT-XS07400.snowflakecomputing.com:443. Incorrect username or password was specified.

The above exception was the direct cause of the following exception:

Traceback (most recent call last):
  File "/Users/harshitchoudhary/Desktop/lyzr-hackathon/code/notebooks/test_superscan_flow.py", line 56, in <module>
    init_database()
  File "/Users/harshitchoudhary/Desktop/lyzr-hackathon/code/graph_rag/db/connection.py", line 324, in init_database
    db.init_db()
  File "/Users/harshitchoudhary/Desktop/lyzr-hackathon/code/graph_rag/db/connection.py", line 185, in init_db
    SQLModel.metadata.create_all(engine)
  File "/opt/miniconda3/lib/python3.12/site-packages/sqlalchemy/sql/schema.py", line 5924, in create_all
    bind._run_ddl_visitor(
  File "/opt/miniconda3/lib/python3.12/site-packages/sqlalchemy/engine/base.py", line 3247, in _run_ddl_visitor
    with self.begin() as conn:
  File "/opt/miniconda3/lib/python3.12/contextlib.py", line 137, in __enter__
    return next(self.gen)
           ^^^^^^^^^^^^^^
  File "/opt/miniconda3/lib/python3.12/site-packages/sqlalchemy/engine/base.py", line 3237, in begin
    with self.connect() as conn:
         ^^^^^^^^^^^^^^
  File "/opt/miniconda3/lib/python3.12/site-packages/sqlalchemy/engine/base.py", line 3273, in connect
    return self._connection_cls(self)
           ^^^^^^^^^^^^^^^^^^^^^^^^^^
  File "/opt/miniconda3/lib/python3.12/site-packages/sqlalchemy/engine/base.py", line 147, in __init__
    Connection._handle_dbapi_exception_noconnection(
  File "/opt/miniconda3/lib/python3.12/site-packages/sqlalchemy/engine/base.py", line 2436, in _handle_dbapi_exception_noconnection
    raise sqlalchemy_exception.with_traceback(exc_info[2]) from e
  File "/opt/miniconda3/lib/python3.12/site-packages/sqlalchemy/engine/base.py", line 145, in __init__
    self._dbapi_connection = engine.raw_connection()
                             ^^^^^^^^^^^^^^^^^^^^^^^
  File "/opt/miniconda3/lib/python3.12/site-packages/sqlalchemy/engine/base.py", line 3297, in raw_connection
    return self.pool.connect()
           ^^^^^^^^^^^^^^^^^^^
  File "/opt/miniconda3/lib/python3.12/site-packages/sqlalchemy/pool/base.py", line 449, in connect
    return _ConnectionFairy._checkout(self)
           ^^^^^^^^^^^^^^^^^^^^^^^^^^^^^^^^
  File "/opt/miniconda3/lib/python3.12/site-packages/sqlalchemy/pool/base.py", line 1264, in _checkout
    fairy = _ConnectionRecord.checkout(pool)
            ^^^^^^^^^^^^^^^^^^^^^^^^^^^^^^^^
  File "/opt/miniconda3/lib/python3.12/site-packages/sqlalchemy/pool/base.py", line 713, in checkout
    rec = pool._do_get()
          ^^^^^^^^^^^^^^
  File "/opt/miniconda3/lib/python3.12/site-packages/sqlalchemy/pool/impl.py", line 179, in _do_get
    with util.safe_reraise():
  File "/opt/miniconda3/lib/python3.12/site-packages/sqlalchemy/util/langhelpers.py", line 224, in __exit__
    raise exc_value.with_traceback(exc_tb)
  File "/opt/miniconda3/lib/python3.12/site-packages/sqlalchemy/pool/impl.py", line 177, in _do_get
    return self._create_connection()
           ^^^^^^^^^^^^^^^^^^^^^^^^^
  File "/opt/miniconda3/lib/python3.12/site-packages/sqlalchemy/pool/base.py", line 390, in _create_connection
    return _ConnectionRecord(self)
           ^^^^^^^^^^^^^^^^^^^^^^^
  File "/opt/miniconda3/lib/python3.12/site-packages/sqlalchemy/pool/base.py", line 675, in __init__
    self.__connect()
  File "/opt/miniconda3/lib/python3.12/site-packages/sqlalchemy/pool/base.py", line 901, in __connect
    with util.safe_reraise():
  File "/opt/miniconda3/lib/python3.12/site-packages/sqlalchemy/util/langhelpers.py", line 224, in __exit__
    raise exc_value.with_traceback(exc_tb)
  File "/opt/miniconda3/lib/python3.12/site-packages/sqlalchemy/pool/base.py", line 897, in __connect
    self.dbapi_connection = connection = pool._invoke_creator(self)
                                         ^^^^^^^^^^^^^^^^^^^^^^^^^^
  File "/opt/miniconda3/lib/python3.12/site-packages/sqlalchemy/engine/create.py", line 646, in connect
    return dialect.connect(*cargs, **cparams)
           ^^^^^^^^^^^^^^^^^^^^^^^^^^^^^^^^^^
  File "/opt/miniconda3/lib/python3.12/site-packages/snowflake/sqlalchemy/snowdialect.py", line 900, in connect
    super().connect(
  File "/opt/miniconda3/lib/python3.12/site-packages/sqlalchemy/engine/default.py", line 625, in connect
    return self.loaded_dbapi.connect(*cargs, **cparams)  # type: ignore[no-any-return]  # NOQA: E501
           ^^^^^^^^^^^^^^^^^^^^^^^^^^^^^^^^^^^^^^^^^^^^
  File "/opt/miniconda3/lib/python3.12/site-packages/snowflake/connector/__init__.py", line 54, in Connect
    return SnowflakeConnection(**kwargs)
           ^^^^^^^^^^^^^^^^^^^^^^^^^^^^^
  File "/opt/miniconda3/lib/python3.12/site-packages/snowflake/connector/connection.py", line 588, in __init__
    self.connect(**kwargs)
  File "/opt/miniconda3/lib/python3.12/site-packages/snowflake/connector/connection.py", line 972, in connect
    self.__open_connection()
  File "/opt/miniconda3/lib/python3.12/site-packages/snowflake/connector/connection.py", line 1371, in __open_connection
    self.authenticate_with_retry(self.auth_class)
  File "/opt/miniconda3/lib/python3.12/site-packages/snowflake/connector/connection.py", line 1704, in authenticate_with_retry
    self._authenticate(auth_instance)
  File "/opt/miniconda3/lib/python3.12/site-packages/snowflake/connector/connection.py", line 1736, in _authenticate
    auth.authenticate(
  File "/opt/miniconda3/lib/python3.12/site-packages/snowflake/connector/auth/_auth.py", line 401, in authenticate
    Error.errorhandler_wrapper(
  File "/opt/miniconda3/lib/python3.12/site-packages/snowflake/connector/errors.py", line 286, in errorhandler_wrapper
    handed_over = Error.hand_to_other_handler(
                  ^^^^^^^^^^^^^^^^^^^^^^^^^^^^
  File "/opt/miniconda3/lib/python3.12/site-packages/snowflake/connector/errors.py", line 344, in hand_to_other_handler
    connection.errorhandler(connection, cursor, error_class, error_value)
  File "/opt/miniconda3/lib/python3.12/site-packages/snowflake/connector/errors.py", line 217, in default_errorhandler
    raise error_class(
sqlalchemy.exc.DatabaseError: (snowflake.connector.errors.DatabaseError) 250001 (08001): Failed to connect to DB: 1234567890@FHWELTT-XS07400.snowflakecomputing.com:443. Incorrect username or password was specified.
(Background on this error at: https://sqlalche.me/e/20/4xp6)
